Workbook
Name Brand: Sheet1!$A$2:$A$17
Name Gallons: Sheet1!$B$2:$B$6
Name Type: Sheet1!$C$3:$C$10

Sheet NEEA HPWH data-SampleExport
A1: ; | B1: CEC Title-24 Residential Compliance Ruleset | O1: Brands | T1: DHWHeater:ASHPType | V1: CSE - DHWHEATER: whASHPType | W1: occurrences
A2: ; | B2: NEEA HPWH make/model data | O2: A. O. Smith | P2: 11 | T2: AO Smith PHPT 60 | U2: 11 | V2: AOSmithPHPT60 | W2: =COUNTIF($X$74:$X$620, V2) -> 7
A3: ; | O3: American | P3: =P2+1 -> 12 | T3: AO Smith PHPT 80 | U3: 12 | V3: AOSmithPHPT80 | W3: =COUNTIF($X$74:$X$620, V3) -> 14
A4: ; | B4: Created: | D4: 7/5/17 - SAC | O4: AquaThermAire | P4: 29 | T4: AO Smith HPTU 50 | U4: 13 | V4: AOSmithHPTU50 | W4: =COUNTIF($X$74:$X$620, V4) -> 31
A5: ; | B5: Last modified: | D5: 03/04/26 - SAC | O5: Bradford White | P5: =P3+1 -> 13 | T5: AO Smith HPTU 66 | U5: 14 | V5: AOSmithHPTU66 | W5: =COUNTIF($X$74:$X$620, V5) -> 27
A6: ; | O6: Direct Energy | P6: 27 | T6: AO Smith HPTU 80 | U6: 15 | V6: AOSmithHPTU80 | W6: =COUNTIF($X$74:$X$620, V6) -> 30
A7: ; | B7: Source Data: | D7: Created from file: HPWH_models_list_2017-04d.xlsx | O7: EcoSense | P7: =P5+1 -> 14 | T7: AO Smith HPTU 80 DR | U7: 31 | V7: AOSmithHPTU80DR | W7: =COUNTIF($X$74:$X$620, V7) -> 0
A8: ; | O8: GE | P8: =P7+1 -> 15 | T8: AO Smith SHPT 50 | U8: 32 | V8: AOSmithSHPT50 | W8: =COUNTIF($X$74:$X$620, V8) -> 2
A9: ; | B9: Mod history: | D9: 03/04/26 - SAC - added new BradfordWhite & SANCO2 models (dev #736) | O9: Kenmore | P9: =P8+1 -> 16 | T9: AO Smith SHPT 66 | U9: 33 | V9: AOSmithSHPT66 | W9: =COUNTIF($X$74:$X$620, V9) -> 0
A10: ; | D10: 10/25/25 - SAC - replaced generic option 'UEF 2 (50 gal)' with 'Standard Design 50 gal HPWH' (dev #518) | O10: Lochinvar | P10: =P9+1 -> 17 | T10: AO Smith SHPT 80 | U10: 34 | V10: AOSmithSHPT80 | W10: =COUNTIF($X$74:$X$620, V10) -> 5
A11: ; | D11: 04/02/25 - SAC - Integrate Tier & UEF data from Sam Larson / Larson Energy Research | O11: Reliance | P11: =P10+1 -> 18 | T11: GE2014 50 | U11: 19 | V11: GE2014 | W11: =COUNTIF($X$74:$X$620, V11) -> 7
A12: ; | D12: 12/19/24 - RJH - Restore the '+' in Column P formula for (generic) tier entries | O12: Rheem | P12: =P11+1 -> 19 | T12: GE2014 50 Eff | U12: 19 | V12: GE2014 | W12: =COUNTIF($X$74:$X$620, V12) -> 7 | X12: was 37
A13: ; | D13: 12/18/24 - RJH - Modified ASHPTypes AeroTherm2023* to BradfordWhiteAeroThermRE2H to match CSE presets; renumbered BradfordWhiteAeroThermRE2H80 to avoid conflict with "WorstCaseMedium" | O13: Rheem Canada | P13: 28 | T13: GE2014 80 | U13: 23 | V13: GE2014_80 | W13: =COUNTIF($X$74:$X$620, V13) -> 6
A14: ; | D14: 11/15/24 - RJH - Removed unnecessary Harvest Thermal ASHPType enums; changed new ASHPType enum values to avoid conflict with Central system enums | O14: Richmond | P14: =P12+1 -> 20 | T14: GE2014 80 Eff | U14: 23 | V14: GE2014_80 | W14: =COUNTIF($X$74:$X$620, V14) -> 6 | X14: was 35
A15: ; | D15: 11/08/24 - RJH - Changed enum number for DHWHeater:ASHPType = AeroTherm2023_50 to avoid duplication | O15: Ruud | P15: =P14+1 -> 21 | T15: GE2014 80 Eff DR | U15: 36 | V15: GE2014_80DR | W15: =COUNTIF($X$74:$X$620, V15) -> 0
A16: ; | D16: 10/30/24 - RJH - Revised Model ID calculation to allow up to 1000 models per Brand | O16: SANCO2 | P16: =P15+1 -> 22 | T16: Rheem HB 50 | U16: 21 | V16: RheemHB50 | W16: =COUNTIF($X$74:$X$620, V16) -> 9
A17: ; | D17: 10/29/24 - RJH - Removed "JA13" tag from all existing Models. Added Brands (Friedrich and LG) and Models from updated list. | O17: State | P17: =P16+1 -> 23 | T17: SANCO2 40 | U17: 16 | V17: SANCO240 | W17: =COUNTIF($X$74:$X$620, V17) -> 11 | X17: 9/2/24 - RJH - passed to CSE as "Sanden40
A18: ; | D18: 09/11/24 - RJH - Added new Harvest Thermal manufacturer/models (mapped to SANCO2 simulation groups) | O18: Stiebel Eltron | P18: =P17+1 -> 24 | T18: SANCO2 80 | U18: 17 | V18: SANCO280 | W18: =COUNTIF($X$74:$X$620, V18) -> 13 | X18: 9/2/24 - RJH - passed to CSE as "Sanden80
A19: ; | D19: 09/10/24 - RJH - Added new SANCO2 simulation group (DHWHeater:ASHPType) 18 = SANCO2 120 | O19: US Craftmaster | P19: =P18+1 -> 25 | T19: SANCO2 120 | U19: 18 | V19: SANCO2120 | W19: =COUNTIF($X$74:$X$620, V19) -> 9 | X19: 9/10/24 - RJH - added (passed to CSE as "Sanden120)
A20: ; | D20: 09/02/24 - RJH - Added new SANCO2 models | O20: Whirlpool | P20: =P19+1 -> 26 | T20: Stiebel 220E | U20: 22 | V20: Stiebel220E | W20: =COUNTIF($X$74:$X$620, V20) -> 1
A21: ; | D21: 08/29/24 - RJH - Renamed "Sanden" to "SANCO2" | O21: Harvest Thermal | P21: 30 | T21: GE2012 50 | U21: 38 | V21: GE2012 | W21: =COUNTIF($X$74:$X$620, V21) -> 1
A22: ; | D22: 04/24/24 - SAC - added new 'generic' Tier 4 and UEF 2.17 options / and updated Tier values throught (w/ data from BL) | O22: Friedrich | P22: =P21+1 -> 31 | T22: Rheem HBDR-45-50 | U22: 39 | V22: RheemHBDR4550 | W22: =COUNTIF($X$74:$X$620, V22) -> 9
A23: ; | D23: 01/29/24 - SAC - added AquaThermAire brand and 4 2-tier models | O23: LG | P23: =P22+1 -> 32 | T23: Rheem HBDR-45-65 | U23: 40 | V23: RheemHBDR4565 | W23: =COUNTIF($X$74:$X$620, V23) -> 9
A24: ; | D24: 07/06/23 - RJH - Added 3 new Bradford White models | O24: (generic) | P24: 99 | T24: Rheem HBDR-45-80 | U24: 41 | V24: RheemHBDR4580 | W24: =COUNTIF($X$74:$X$620, V24) -> 9
A25: ; | D25: 05/24/23 - RJH - 1. Deleted columns J (EF), K (UEF), AB (Energy Factor NC†), and AD (Uniform Energy Factor NC†) to avoid misinterpretation/misuse of these values; and 2. Edited RheemXE* enumeration values columns AI (now AC: CF1R T11_HeatPumpWaterHeaterModel) and, thereby, M (RptHPWHModel) | T25: Rheem HBDR-22-50 | U25: 42 | V25: RheemHBDR2250 | W25: =COUNTIF($X$74:$X$620, V25) -> 4
A26: ; | D26: 01/18/23 - SAC - added ~60 new models, some of which map to latest HPWHSim preset AOSmithHPTS** | T26: Rheem HBDR-22-65 | U26: 43 | V26: RheemHBDR2265 | W26: =COUNTIF($X$74:$X$620, V26) -> 4
A27: ; | D27: 12/26/22 - SAC - added ModelNum & RptHPWHModel columns to enable this one table to be used in both Res & CBECC rulesets | T27: Rheem HBDR-22-80 | U27: 44 | V27: RheemHBDR2280 | W27: =COUNTIF($X$74:$X$620, V27) -> 4
A28: ; | D28: 11/09/22 - SAC - added 40 new Rheem/Ruud/Richmond models (ported from Res spreadsheet) | T28: Bradford White 2020 65 | U28: 58 | V28: BWC202065 | W28: =COUNTIF($X$74:$X$620, V28) -> 2 | X28: 6/16/20 - SAC - added
A29: ; | D29: 08/25/21 - SAC - transformed Res table into Com | T29: Rheem 2020 Premium 40 | U29: 59 | V29: Rheem2020Prem40 | W29: =COUNTIF($X$74:$X$620, V29) -> 47
A30: ; | D30: 06/17/21 - SAC - added 4 NEEA tier 3 generic model selections | T30: Rheem 2020 Premium 50 | U30: 60 | V30: Rheem2020Prem50 | W30: =COUNTIF($X$74:$X$620, V30) -> 48
A31: ; | D31: 01/31/21 - SAC - added cold weather and commercial presets (no NEEA mods); and updated demand responsive enum strings to include 'JA13' | T31: Rheem 2020 Premium 65 | U31: 61 | V31: Rheem2020Prem65 | W31: =COUNTIF($X$74:$X$620, V31) -> 48
A32: ; | D32: 12/11/20 - SAC - added new equip from NEEA's 10/14,23 & 11/23 updates | T32: Rheem 2020 Premium 80 | U32: 62 | V32: Rheem2020Prem80 | W32: =COUNTIF($X$74:$X$620, V32) -> 48
A33: ; | D33: 12/11/20 - SAC - added columns AB & AE to facilitate ruleset updates | T33: Rheem 2020 Builder 40 | U33: 63 | V33: Rheem2020Build40 | W33: =COUNTIF($X$74:$X$620, V33) -> 7
A34: ; | D34: 12/04/20 - SAC - added JA13 (demand response) compatible flags by model | T34: Rheem 2020 Builder 50 | U34: 64 | V34: Rheem2020Build50 | W34: =COUNTIF($X$74:$X$620, V34) -> 7
A35: ; | D35: 6/16/20 - SAC - integrate new NEEA HPWH selections from 6/2 listing | T35: Rheem 2020 Builder 65 | U35: 65 | V35: Rheem2020Build65 | W35: =COUNTIF($X$74:$X$620, V35) -> 7
A36: ; | D36: 5/23/20 - SAC - added lookup columns for UEF & EF | T36: Rheem 2020 Builder 80 | U36: 66 | V36: Rheem2020Build80 | W36: =COUNTIF($X$74:$X$620, V36) -> 7
A37: ; | D37: 11/16/17 - SAC - complete Rheem additions (6 sim +) | T37: Nyle C60A-CWP | U37: 67 | V37: NyleC60A_CWP_SP | W37: =COUNTIF($X$74:$X$620, V37) -> 0 | X37: SAC 6/23/20 - added cold wthr package presets
A38: ; | D38: 8/10/17 - SAC - added generic / UEF 2 option | T38: Nyle C90A-CWP | U38: 68 | V38: NyleC90A_CWP_SP | W38: =COUNTIF($X$74:$X$620, V38) -> 0
A39: ; | D39: 7/19/17 - SAC - updated Sanden model options | T39: Nyle C125A-CWP | U39: 69 | V39: NyleC125A_CWP_SP | W39: =COUNTIF($X$74:$X$620, V39) -> 0
A40: ; | T40: Nyle C185A-CWP | U40: 70 | V40: NyleC185A_CWP_SP | W40: =COUNTIF($X$74:$X$620, V40) -> 0
...

Sheet Enum List
A32: ="2, "&'NEEA HPWH data-SampleExport'!C87&", """&'NEEA HPWH data-SampleExport'!R87&"""" -> 2, A. O. Smith, "HPTS-50 2** (50 gal)"
A33: ="2, "&'NEEA HPWH data-SampleExport'!C88&", """&'NEEA HPWH data-SampleExport'!R88&"""" -> 2, A. O. Smith, "HPS10-50H45DV 2** (50 gal)"
A34: ="2, "&'NEEA HPWH data-SampleExport'!C89&", """&'NEEA HPWH data-SampleExport'!R89&"""" -> 2, A. O. Smith, "HPTS-66 2** (66 gal)"
A35: ="2, "&'NEEA HPWH data-SampleExport'!C90&", """&'NEEA HPWH data-SampleExport'!R90&"""" -> 2, A. O. Smith, "HPS10-66H45DV 2** (66 gal)"
A36: ="2, "&'NEEA HPWH data-SampleExport'!C91&", """&'NEEA HPWH data-SampleExport'!R91&"""" -> 2, A. O. Smith, "HPTS-80 2** (80 gal)"
A37: ="2, "&'NEEA HPWH data-SampleExport'!C92&", """&'NEEA HPWH data-SampleExport'!R92&"""" -> 2, A. O. Smith, "HPS10-80H45DV 2** (80 gal)"
A38: ="2, "&'NEEA HPWH data-SampleExport'!C93&", """&'NEEA HPWH data-SampleExport'!R93&"""" -> 2, A. O. Smith, "FPTU 50 120 (50 gal)"
A39: ="2, "&'NEEA HPWH data-SampleExport'!C94&", """&'NEEA HPWH data-SampleExport'!R94&"""" -> 2, A. O. Smith, "FPTU 66 120 (66 gal)"
A40: ="2, "&'NEEA HPWH data-SampleExport'!C95&", """&'NEEA HPWH data-SampleExport'!R95&"""" -> 2, A. O. Smith, "FPTU 80 120 (80 gal)"
A41: ="2, "&'NEEA HPWH data-SampleExport'!C96&", """&'NEEA HPWH data-SampleExport'!R96&"""" -> 2, A. O. Smith, "HHPT 80 102 (80 gal)"
A42: ="2, "&'NEEA HPWH data-SampleExport'!C97&", """&'NEEA HPWH data-SampleExport'!R97&"""" -> 2, A. O. Smith, "HP10-50H45DV (50 gal)"
A43: ="2, "&'NEEA HPWH data-SampleExport'!C98&", """&'NEEA HPWH data-SampleExport'!R98&"""" -> 2, A. O. Smith, "HP10-80H45DV (80 gal)"
... A56: ="2, "&'NEEA HPWH data-SampleExport'!C111&", """&'NEEA HPWH data-SampleExport'!R111&"""" -> 2, A. O. Smith, "PHPT 80 (80 gal)"
A57: ="2, "&'NEEA HPWH data-SampleExport'!C119&", """&'NEEA HPWH data-SampleExport'!R119&"""" -> 2, American, "HPS10250H045DV 2** (50 gal)"
A58: ="2, "&'NEEA HPWH data-SampleExport'!C120&", """&'NEEA HPWH data-SampleExport'!R120&"""" -> 2, American, "HPS10266H045DV 2** (66 gal)"
A59: ="2, "&'NEEA HPWH data-SampleExport'!C121&", """&'NEEA HPWH data-SampleExport'!R121&"""" -> 2, American, "HPS10280H045DV 2** (80 gal)"
A60: ="2, "&'NEEA HPWH data-SampleExport'!C122&", """&'NEEA HPWH data-SampleExport'!R122&"""" -> 2, American, "HPE10260H045DV (60 gal)"
A61: ="2, "&'NEEA HPWH data-SampleExport'!C123&", """&'NEEA HPWH data-SampleExport'!R123&"""" -> 2, American, "HPE10280H045DV (80 gal)"
A62: ="2, "&'NEEA HPWH data-SampleExport'!C124&", """&'NEEA HPWH data-SampleExport'!R124&"""" -> 2, American, "HPE6280H045DV 102 (80 gal)"
A63: ="2, "&'NEEA HPWH data-SampleExport'!C125&", """&'NEEA HPWH data-SampleExport'!R125&"""" -> 2, American, "HPHE10250H045DV 120 (50 gal)"
A64: ="2, "&'NEEA HPWH data-SampleExport'!C126&", """&'NEEA HPWH data-SampleExport'!R126&"""" -> 2, American, "HPHE10250H045DVN 120 (50 gal)"
A65: ="2, "&'NEEA HPWH data-SampleExport'!C127&", """&'NEEA HPWH data-SampleExport'!R127&"""" -> 2, American, "HPHE10250H045DVDR 130 (50 gal)"
A66: ="2, "&'NEEA HPWH data-SampleExport'!C128&", """&'NEEA HPWH data-SampleExport'!R128&"""" -> 2, American, "HPHE10266H045DV 120 (66 gal)"
A67: ="2, "&'NEEA HPWH data-SampleExport'!C129&", """&'NEEA HPWH data-SampleExport'!R129&"""" -> 2, American, "HPHE10266H045DVN 120 (66 gal)"
A68: ="2, "&'NEEA HPWH data-SampleExport'!C130&", """&'NEEA HPWH data-SampleExport'!R130&"""" -> 2, American, "HPHE10266H045DVDR 130 (66 gal)"
... A79: ="2, "&'NEEA HPWH data-SampleExport'!C141&", """&'NEEA HPWH data-SampleExport'!R141&"""" -> 2, AquaThermAire, "CHT2021-48C (54 gal)"
A80: ="2, "&'NEEA HPWH data-SampleExport'!C151&", """&'NEEA HPWH data-SampleExport'!R151&"""" -> 2, Bradford White, "RE2H50S*-***** (50 gal)"
A81: ="2, "&'NEEA HPWH data-SampleExport'!C152&", """&'NEEA HPWH data-SampleExport'!R152&"""" -> 2, Bradford White, "RE2H65T*-***** (65 gal)"
A82: ="2, "&'NEEA HPWH data-SampleExport'!C153&", """&'NEEA HPWH data-SampleExport'!R153&"""" -> 2, Bradford White, "RE2H80T*-***** (80 gal)"
A83: ="2, "&'NEEA HPWH data-SampleExport'!C154&", """&'NEEA HPWH data-SampleExport'!R154&"""" -> 2, Bradford White, "RE2H50R10B-1NCWT (50 gal)"
A84: ="2, "&'NEEA HPWH data-SampleExport'!C155&", """&'NEEA HPWH data-SampleExport'!R155&"""" -> 2, Bradford White, "RE2H65T10-1NCWT (65 gal)"
A85: ="2, "&'NEEA HPWH data-SampleExport'!C156&", """&'NEEA HPWH data-SampleExport'!R156&"""" -> 2, Bradford White, "RE2H80R10B-1NCWT (80 gal)"
A86: ="2, "&'NEEA HPWH data-SampleExport'!C157&", """&'NEEA HPWH data-SampleExport'!R157&"""" -> 2, Bradford White, "RE2H50S6-1NCWT (50 gal)"
A87: ="2, "&'NEEA HPWH data-SampleExport'!C158&", """&'NEEA HPWH data-SampleExport'!R158&"""" -> 2, Bradford White, "RE2H65T6-1NCWT (65 gal)"
A88: ="2, "&'NEEA HPWH data-SampleExport'!C159&", """&'NEEA HPWH data-SampleExport'!R159&"""" -> 2, Bradford White, "RE2H80T6-1NCWT (80 gal)"
A89: ="2, "&'NEEA HPWH data-SampleExport'!C160&", """&'NEEA HPWH data-SampleExport'!R160&"""" -> 2, Direct Energy, "ECEPH40 T2 RH375-15 (40 gal)"
A90: ="2, "&'NEEA HPWH data-SampleExport'!C161&", """&'NEEA HPWH data-SampleExport'!R161&"""" -> 2, Direct Energy, "ECEPH50 T2 RH375-15 (50 gal)"
A91: ="2, "&'NEEA HPWH data-SampleExport'!C162&", """&'NEEA HPWH data-SampleExport'!R162&"""" -> 2, Direct Energy, "ECEPH65 T2 RH375-15 (65 gal)"
... A105: ="2, "&'NEEA HPWH data-SampleExport'!C176&", """&'NEEA HPWH data-SampleExport'!R176&"""" -> 2, EcoSense, "HB50ES (50 gal)"
A106: ="2, "&'NEEA HPWH data-SampleExport'!C193&", """&'NEEA HPWH data-SampleExport'!R193&"""" -> 2, GE, "BEH50DCEJSB (50 gal)"
...

Sheet Sheet1
A1: Brand | B1: Gallons | C1: Type
A2: A. O. Smith | B2: 43 | C2: AO Smith HPTU 50
A3: American | B3: 50 | C3: AO Smith HPTU 66
A4: Bradford White | B4: 60 | C4: AO Smith HPTU 80
A5: EcoSense | B5: 66 | C5: AO Smith PHPT 60
A6: GE | B6: 80 | C6: AO Smith PHPT 80
A7: Kenmore | C7: GE 2014 50
A8: Lochinvar | C8: GE 2014 80
A9: Reliance | C9: Rheem HB 50
A10: Rheem | C10: Stiebel 220E
A11: Richmond | C11: GE 2012 50
A12: Ruud
A13: Sanden
A14: State
A15: Stiebel Eltron
A16: US Craftmaster
A17: Whirlpool
A18: (generic)
